2025-10-19 20:47:28,646 - app.modules.dataset.routes - ERROR - Exception while create dataset data in Zenodo Failed to create deposition. Error details: {'status': 403, 'message': 'Permission denied.'}
Traceback (most recent call last):
  File "/home/esteban/uvlhub_practicas/app/modules/dataset/routes.py", line 69, in create_dataset
    zenodo_response_json = zenodo_service.create_new_deposition(dataset)
                           ^^^^^^^^^^^^^^^^^^^^^^^^^^^^^^^^^^^^^^^^^^^^^
  File "/home/esteban/uvlhub_practicas/app/modules/zenodo/services.py", line 178, in create_new_deposition
    raise Exception(error_message)
Exception: Failed to create deposition. Error details: {'status': 403, 'message': 'Permission denied.'}
2025-10-19 20:50:33,979 - app.modules.dataset.routes - ERROR - Exception while create dataset data in Zenodo Failed to create deposition. Error details: {'status': 403, 'message': 'Permission denied.'}
Traceback (most recent call last):
  File "/home/esteban/uvlhub_practicas/app/modules/dataset/routes.py", line 69, in create_dataset
    zenodo_response_json = zenodo_service.create_new_deposition(dataset)
                           ^^^^^^^^^^^^^^^^^^^^^^^^^^^^^^^^^^^^^^^^^^^^^
  File "/home/esteban/uvlhub_practicas/app/modules/zenodo/services.py", line 178, in create_new_deposition
    raise Exception(error_message)
Exception: Failed to create deposition. Error details: {'status': 403, 'message': 'Permission denied.'}
2025-10-19 20:51:48,009 - app.modules.dataset.routes - ERROR - Exception while create dataset data in Zenodo Failed to create deposition. Error details: {'status': 403, 'message': 'Permission denied.'}
Traceback (most recent call last):
  File "/home/esteban/uvlhub_practicas/app/modules/dataset/routes.py", line 69, in create_dataset
    zenodo_response_json = zenodo_service.create_new_deposition(dataset)
                           ^^^^^^^^^^^^^^^^^^^^^^^^^^^^^^^^^^^^^^^^^^^^^
  File "/home/esteban/uvlhub_practicas/app/modules/zenodo/services.py", line 178, in create_new_deposition
    raise Exception(error_message)
Exception: Failed to create deposition. Error details: {'status': 403, 'message': 'Permission denied.'}
2025-10-19 20:57:40,651 - app.modules.dataset.routes - ERROR - Exception while create dataset data in Zenodo Failed to create deposition. Error details: {'status': 403, 'message': 'Permission denied.'}
Traceback (most recent call last):
  File "/home/esteban/uvlhub_practicas/app/modules/dataset/routes.py", line 69, in create_dataset
    zenodo_response_json = zenodo_service.create_new_deposition(dataset)
                           ^^^^^^^^^^^^^^^^^^^^^^^^^^^^^^^^^^^^^^^^^^^^^
  File "/home/esteban/uvlhub_practicas/app/modules/zenodo/services.py", line 178, in create_new_deposition
    raise Exception(error_message)
Exception: Failed to create deposition. Error details: {'status': 403, 'message': 'Permission denied.'}
2025-10-19 20:58:55,374 - app.modules.dataset.routes - ERROR - Exception while create dataset data in Zenodo Failed to create deposition. Error details: {'status': 403, 'message': 'Permission denied.'}
Traceback (most recent call last):
  File "/home/esteban/uvlhub_practicas/app/modules/dataset/routes.py", line 69, in create_dataset
    zenodo_response_json = zenodo_service.create_new_deposition(dataset)
                           ^^^^^^^^^^^^^^^^^^^^^^^^^^^^^^^^^^^^^^^^^^^^^
  File "/home/esteban/uvlhub_practicas/app/modules/zenodo/services.py", line 178, in create_new_deposition
    raise Exception(error_message)
Exception: Failed to create deposition. Error details: {'status': 403, 'message': 'Permission denied.'}
